Workbook
Name COMPRA: Listas!$F$3:$F$4
Name COTIZADO: Listas!$G$3:$G$4
Name ESTADO: Listas!$B$3:$B$10
Name ListaDepartamentos: TablaDepartamentos[departamento]
Name TipoEmpresa: TablaTipoEmpresa[Tipo empresa]
Name Vendedor: TablaVendendores[Vendedor]

Sheet Datos
A1: N° | B1: Vendedor | C1: Obra / Proyecto | D1: Departamento | E1: Ciudad | F1: Dirección | G1: Tipo de empresa | H1: Empresa | I1: Contacto Empresa | J1: Tel. contacto empresa (AUTO) | K1: Estado | L1: Fecha | M1: ¿Quién compra? | N1: Contratista eléctrico | O1: Contacto contratista | P1: Tel. contratista (AUTO) | Q1: Cotizado | R1: Notas | S1: Link ubicación
A2: =ROW(TablaDatos[[#This Row],[N°]])-1 -> 1 | B2: JPO | C2: Obra Prueba | D2: Bogotá | E2: Bogotá | F2: Dirección de prueba | G2: Constructora | H2: Prueba Constructora | I2: Contacto constructora | J2: =_xlfn.XLOOKUP(TablaDatos[[#This Row],[Contacto Empresa]],TablaContactos[Contacto],TablaContactos[Celular],"",0) -> 111 111 11 11 | K2: Estructura | M2: Contratista | N2: Prueba Eléctrico | O2: Contacto eléctrico | P2: =_xlfn.XLOOKUP(TablaDatos[[#This Row],[Contacto contratista]],TablaContactos[Contacto],TablaContactos[Celular],"",0) -> 222 222 22 22 | Q2: Si | S2: https://maps.app.goo.gl/RVM2NKvi1Evxp8m48
A3: =ROW(TablaDatos[[#This Row],[N°]])-1 -> 2 | J3: =_xlfn.XLOOKUP(TablaDatos[[#This Row],[Contacto Empresa]],TablaContactos[Contacto],TablaContactos[Celular],"",0) | P3: =_xlfn.XLOOKUP(TablaDatos[[#This Row],[Contacto contratista]],TablaContactos[Contacto],TablaContactos[Celular],"",0)
A4: =ROW(TablaDatos[[#This Row],[N°]])-1 -> 3 | J4: =_xlfn.XLOOKUP(TablaDatos[[#This Row],[Contacto Empresa]],TablaContactos[Contacto],TablaContactos[Celular],"",0) | P4: =_xlfn.XLOOKUP(TablaDatos[[#This Row],[Contacto contratista]],TablaContactos[Contacto],TablaContactos[Celular],"",0)
A5: =ROW(TablaDatos[[#This Row],[N°]])-1 -> 4 | J5: =_xlfn.XLOOKUP(TablaDatos[[#This Row],[Contacto Empresa]],TablaContactos[Contacto],TablaContactos[Celular],"",0) | P5: =_xlfn.XLOOKUP(TablaDatos[[#This Row],[Contacto contratista]],TablaContactos[Contacto],TablaContactos[Celular],"",0)
A6: =ROW(TablaDatos[[#This Row],[N°]])-1 -> 5 | J6: =_xlfn.XLOOKUP(TablaDatos[[#This Row],[Contacto Empresa]],TablaContactos[Contacto],TablaContactos[Celular],"",0) | P6: =_xlfn.XLOOKUP(TablaDatos[[#This Row],[Contacto contratista]],TablaContactos[Contacto],TablaContactos[Celular],"",0)
A7: =ROW(TablaDatos[[#This Row],[N°]])-1 -> 6 | J7: =_xlfn.XLOOKUP(TablaDatos[[#This Row],[Contacto Empresa]],TablaContactos[Contacto],TablaContactos[Celular],"",0) | P7: =_xlfn.XLOOKUP(TablaDatos[[#This Row],[Contacto contratista]],TablaContactos[Contacto],TablaContactos[Celular],"",0)
A8: =ROW(TablaDatos[[#This Row],[N°]])-1 -> 7 | J8: =_xlfn.XLOOKUP(TablaDatos[[#This Row],[Contacto Empresa]],TablaContactos[Contacto],TablaContactos[Celular],"",0) | P8: =_xlfn.XLOOKUP(TablaDatos[[#This Row],[Contacto contratista]],TablaContactos[Contacto],TablaContactos[Celular],"",0)
A9: =ROW(TablaDatos[[#This Row],[N°]])-1 -> 8 | J9: =_xlfn.XLOOKUP(TablaDatos[[#This Row],[Contacto Empresa]],TablaContactos[Contacto],TablaContactos[Celular],"",0) | P9: =_xlfn.XLOOKUP(TablaDatos[[#This Row],[Contacto contratista]],TablaContactos[Contacto],TablaContactos[Celular],"",0)
A10: =ROW(TablaDatos[[#This Row],[N°]])-1 -> 9 | J10: =_xlfn.XLOOKUP(TablaDatos[[#This Row],[Contacto Empresa]],TablaContactos[Contacto],TablaContactos[Celular],"",0) | P10: =_xlfn.XLOOKUP(TablaDatos[[#This Row],[Contacto contratista]],TablaContactos[Contacto],TablaContactos[Celular],"",0)
A11: =ROW(TablaDatos[[#This Row],[N°]])-1 -> 10 | J11: =_xlfn.XLOOKUP(TablaDatos[[#This Row],[Contacto Empresa]],TablaContactos[Contacto],TablaContactos[Celular],"",0) | P11: =_xlfn.XLOOKUP(TablaDatos[[#This Row],[Contacto contratista]],TablaContactos[Contacto],TablaContactos[Celular],"",0)

Sheet Región
B1: departamentoID | C1: departamento | F1: municipioID | G1: municipio | H1: departamentoID | J1: {=_xlfn.LET( _xlpm.matriz,_xlfn.ANCHORARRAY( Región!$K$1), _xlpm.columna_n, MATCH(TablaDatos[ [#This Row],[Departamento] ], INDEX(_xlpm.matriz, 1, 0), 0), _xlpm.rango_col, INDEX(_xlpm.matriz, 0, _xlpm.columna_n), INDEX(_xlpm.rango_col, 2) : INDEX(_xlpm.rango_col, COUNTA(_xlpm.rango_col)) )} -> #VALUE! | K1: {=_xlfn.LET( _xlpm.deps, TablaDepartamentos[departamento], IFERROR(_xlfn.DROP(_xlfn.REDUCE("", _xlpm.deps, _xlfn.LAMBDA(_xlpm.matriz,_xlpm.d, _xlfn.LET( _xlpm.idDep, _xlfn.XLOOKUP(_xlpm.d, TablaDepartamentos[departamento], TablaDepartamentos[departamentoID]), _xlpm.muni, _xlfn._xlws.FILTER(TablaMunicipios[municipio], TablaMunicipios[departamentoID]=_xlpm.idDep, " "), _xlfn.HSTACK(_xlpm.matriz, _xlfn.VSTACK(_xlpm.d, _xlpm.muni)) ) )), , 1), "") )} -> Bogotá | L1: Amazonas | M1: Antioquia | N1: Arauca | O1: Atlántico | P1: Bolívar | Q1: Boyacá | R1: Caldas | S1: Caquetá | T1: Casanare | U1: Cauca | V1: Cesar | W1: Chocó | X1: Córdoba | Y1: Cundinamarca | Z1: Guainía | AA1: Guaviare | AB1: Huila | AC1: La Guajira | AD1: Magdalena | AE1: Meta | AF1: Nariño | AG1: Norte de Santander | AH1: Putumayo | AI1: Quindío | AJ1: Risaralda | AK1: Archipiélago de San Andrés, Providencia y Santa Catalina | AL1: Santander | AM1: Sucre | AN1: Tolima | AO1: Valle del Cauca | AP1: Vaupés | AQ1: Vichada
B2: 1 | C2: Bogotá | F2: 1 | G2: Bogotá | H2: 1 | J2: {=_xlfn.LET( _xlpm.matriz,_xlfn.ANCHORARRAY( Región!$K$1), _xlpm.dep, INDIRECT("FC[-1]", FALSE), _xlpm.col_n, IFERROR(MATCH(_xlpm.dep, INDEX(_xlpm.matriz, 1, 0), 0), 0), IF(_xlpm.col_n=0, Región!$WZZ$1, _xlfn.LET( _xlpm.rango_col, INDEX(_xlpm.matriz, 0, _xlpm.col_n), INDEX(_xlpm.rango_col, 2) : INDEX(_xlpm.rango_col, COUNTA(_xlpm.rango_col)) ) ) )} -> 0 | K2: Bogotá | L2: Leticia | M2: Medellín | N2: Arauca | O2: Barranquilla | P2: Cartagena de Indias | Q2: Tunja | R2: Manizales | S2: Florencia | T2: Yopal | U2: Popayán | V2: Valledupar | W2: Quibdó | X2: Montería | Y2: Agua de Dios | Z2: Inírida | AA2: San José del Guaviare | AB2: Neiva | AC2: Riohacha | AD2: Santa Marta | AE2: Villavicencio | AF2: Pasto | AG2: Cúcuta | AH2: Mocoa | AI2: Armenia | AJ2: Pereira | AK2: San Andrés | AL2: Bucaramanga | AM2: Sincelejo | AN2: Ibagué | AO2: Cali | AP2: Mitú | AQ2: Puerto Carreño
B3: 2 | C3: Amazonas | F3: 2 | G3: Leticia | H3: 2 | L3: El Encanto | M3: Abejorral | N3: Arauquita | O3: Baranoa | P3: Achí | Q3: Almeida | R3: Aguadas | S3: Albania | T3: Aguazul | U3: Almaguer | V3: Aguachica | W3: Acandí | X3: Ayapel | Y3: Albán | Z3: Barranco Minas | AA3: Calamar | AB3: Acevedo | AC3: Albania | AD3: Algarrobo | AE3: Acacías | AF3: San José de Albán | AG3: Ábrego | AH3: Colón | AI3: Buenavista | AJ3: Apía | AL3: Aguada | AM3: Betulia | AN3: Alvarado | AO3: Alcalá | AP3: Carurú | AQ3: Cumaribo
B4: 3 | C4: Antioquia | F4: 3 | G4: El Encanto | H4: 2 | L4: La Chorrera | M4: Abriaquí | N4: Cravo Norte | O4: Campo de la Cruz | P4: Altos del Rosario | Q4: Aquitania | R4: Anserma | S4: Belén de los Andaquíes | T4: Monterrey | U4: Argelia | V4: Astrea | W4: Alto Baudó | X4: Buenavista | Y4: Anapoima | Z4: Cacahual | AA4: El Retorno | AB4: Colombia | AC4: Barrancas | AD4: Aracataca | AE4: Barranca de Upía | AF4: Aldana | AG4: Arboledas | AH4: Puerto Asís | AI4: Calarcá | AJ4: Balboa | AL4: Albania | AM4: Buenavista | AN4: Ambalema | AO4: Andalucía | AP4: Papunaua | AQ4: La Primavera
B5: 4 | C5: Arauca | F5: 4 | G5: La Chorrera | H5: 2 | L5: La Pedrera | M5: Alejandría | N5: Fortul | O5: Candelaria | P5: Arjona | Q5: Arcabuco | R5: Aranzazu | S5: Cartagena del Chairá | T5: Nunchía | U5: Balboa | V5: Becerril | W5: El Atrato | X5: Canalete | Y5: Anolaima | Z5: La Guadalupe | AA5: Miraflores | AB5: Aipe | AC5: Dibulla | AD5: Ariguaní | AE5: Cabuyaro | AF5: Ancuya | AG5: Bochalema | AH5: Puerto Caicedo | AI5: Circasia | AJ5: Belén de Umbría | AL5: Aratoca | AM5: Caimito | AN5: Estado Anzoátegui | AO5: Ansermanuevo | AP5: Taraira | AQ5: Santa Rosalía
B6: 5 | C6: Atlántico | F6: 5 | G6: La Pedrera | H6: 2 | L6: La Victoria | M6: Amagá | N6: Puerto Rondón | O6: Galapa | P6: Arenal | Q6: Belén | R6: Belalcázar | S6: Curillo | T6: Orocué | U6: Bolívar | V6: Bosconia | W6: Bagadó | X6: Cereté | Y6: Apulo | Z6: Mapiripán | AB6: Algeciras | AC6: Distracción | AD6: Cerro de San Antonio | AE6: Castilla la Nueva | AF6: Arboleda | AG6: Bucarasica | AH6: Puerto Guzmán | AI6: Córdoba | AJ6: Dosquebradas | AL6: Barbosa | AM6: Colosó | AN6: Ataco | AO6: Argelia | AP6: Yavaraté
B7: 6 | C7: Bolívar | F7: 6 | G7: La Victoria | H7: 2 | L7: Mirití-Paraná | M7: Amalfi | N7: Saravena | O7: Juan de Acosta | P7: Arroyohondo | Q7: Berbeo | R7: Chinchiná | S7: El Doncello | T7: Paz de Ariporo | U7: Buenos Aires | V7: Chimichagua | W7: Bahía Solano | X7: Chimá | Y7: Arbeláez | Z7: Morichal Nuevo | AB7: Altamira | AC7: El Molino | AD7: Chibolo | AE7: Cubarral | AF7: Barbacoas | AG7: Cácota | AH7: Puerto Leguízamo | AI7: Filandia | AJ7: Guática | AL7: Barichara | AM7: Coveñas | AN7: Cajamarca | AO7: Bolívar
B8: 7 | C8: Boyacá | F8: 7 | G8: Mirití-Paraná | H8: 2 | L8: Puerto Alegría | M8: Andes | N8: Tame | O8: Luruaco | P8: Barranco de Loba | Q8: Betéitiva | R8: Filadelfia | S8: El Paujil | T8: Pore | U8: Cajibío | V8: Chiriguaná | W8: Bajo Baudó | X8: Chinú | Y8: Beltrán | Z8: Pana Pana | AB8: Baraya | AC8: Fonseca | AD8: Ciénaga | AE8: Cumaral | AF8: Belén | AG8: Cáchira | AH8: Sibundoy | AI8: Génova | AJ8: La Celia | AL8: Barrancabermeja | AM8: Chalán | AN8: Carmen de Apicalá | AO8: Buenaventura
B9: 8 | C9: Caldas | F9: 8 | G9: Puerto Alegría | H9: 2 | L9: Puerto Arica | M9: Angelópolis | O9: Malambo | P9: Calamar | Q9: Boavita | R9: La Dorada | S9: La Montañita | T9: Recetor | U9: Caldono | V9: Curumaní | W9: Bojayá | X9: Ciénaga de Oro | Y9: Bituima | Z9: Puerto Colombia | AB9: Campoalegre | AC9: Hatonuevo | AD9: Concordia | AE9: El Calvario | AF9: Arboleda | AG9: Chinácota | AH9: Orito | AI9: La Tebaida | AJ9: La Virginia | AL9: Betulia | AM9: Corozal | AN9: Casabianca | AO9: Buga
B10: 9 | C10: Caquetá | F10: 9 | G10: Puerto Arica | H10: 2 | L10: Puerto Nariño | M10: Angostura | O10: Manatí | P10: Cantagallo | Q10: Boyacá | R10: La Merced | S10: Milán | T10: Sabanalarga | U10: Caloto | V10: El Copey | W10: Carmen del Darién | X10: Cotorra | Y10: Bojacá | Z10: San Felipe | AB10: Colombia | AC10: La Jagua del Pilar | AD10: El Banco | AE10: El Castillo | AF10: Buesaco | AG10: Chitagá | AH10: San Francisco | AI10: Montenegro | AJ10: Marsella | AL10: Bolívar | AM10: El Roble | AN10: Chaparral | AO10: Bugalagrande
B11: 10 | C11: Casanare | F11: 10 | G11: Puerto Nariño | H11: 2 | L11: Puerto Santander | M11: Anorí | O11: Palmar de Varela | P11: El Carmen de Bolívar | Q11: Briceño | R11: La Victoria | S11: Morelia | T11: Sácama | U11: Corinto | V11: El Paso | W11: Cértegui | X11: La Apartada | Y11: Cabrera | AB11: Guadalupe | AC11: Maicao | AD11: El Piñón | AE11: El Dorado | AF11: Chachagüí | AG11: Convención | AH11: San Miguel | AI11: Pijao | AJ11: Mistrató | AL11: Cabrera | AM11: Galeras | AN11: Coello | AO11: Caicedonia
B12: 11 | C12: Cauca | F12: 11 | G12: Puerto Santander | H12: 2 | L12: Tarapacá | M12: Santa Fe de Antioquia | O12: Piojó | P12: Cicuco | Q12: Buenavista | R12: Manzanares | S12: Puerto Rico | T12: San Luis de Palenque | U12: El Tambo | V12: Gamarra | W12: Condoto | X12: Santa Cruz de Lorica | Y12: Cachipay | AB12: Garzón | AC12: Manaure | AD12: El Retén | AE12: Fuente de Oro | AF12: Colón | AG12: Cundinamarca | AH12: Santiago de Chile | AI12: Quimbaya | AJ12: Pueblo Rico | AL12: California | AM12: Guaranda | AN12: Coyaima | AO12: Calima
B13: 12 | C13: Cesar | F13: 12 | G13: Tarapacá | H13: 2 | M13: Anzá | O13: Polonuevo | P13: Clemencia | Q13: Busbanzá | R13: Marmato | S13: San José del Fragua | T13: Támara | U13: Florencia | V13: La Gloria | W13: Cantón de San Pablo | X13: Los Córdobas | Y13: Cajicá | AB13: Gigante | AC13: San Juan del Cesar | AD13: Fundación | AE13: Granada | AF13: Consacá | AG13: Durania | AH13: Villagarzón | AI13: Salento | AJ13: Quinchía | AL13: Capitanejo | AM13: La Unión | AN13: Cunday | AO13: Candelaria
B14: 13 | C14: Chocó | F14: 13 | G14: Medellín | H14: 3 | M14: Apartadó | O14: Ponedera | P14: Córdoba | Q14: Caldas | R14: Marquetalia | S14: San Vicente del Caguán | T14: Tauramena | U14: Guachené | V14: La Jagua de Ibirico | W14: El Carmen de Atrato | X14: Momil | Y14: Caparrapí | AB14: Hobo | AC14: Uribia | AD14: Guamal | AE14: Guamal | AF14: Contadero | AG14: El Carmen | AJ14: Santa Rosa de Cabal | AL14: Carcasí | AM14: Los Palmitos | AN14: Dolores | AO14: Cartago
B15: 14 | C15: Córdoba | F15: 14 | G15: Abejorral | H15: 3 | M15: Arboletes | O15: Puerto Colombia | P15: El Guamo | Q15: Campohermoso | R15: Marulanda | S15: Solano | T15: Trinidad | U15: Guapi | V15: Manaure Balcón del Cesar | W15: Litoral del San Juan | X15: Montelíbano | Y15: Cáqueza | AB15: Íquira | AC15: Urumita | AD15: Nueva Granada | AE15: Mapiripán | AF15: Córdoba | AG15: El Tarra | AJ15: Santuario | AL15: Cepitá | AM15: Majagual | AN15: El Espinal | AO15: Dagua
B16: 15 | C16: Cundinamarca | F16: 15 | G16: Abriaquí | H16: 3 | M16: Argelia | O16: Repelón | P16: El Peñón | Q16: Cerinza | R16: Neira | S16: Solita | T16: Villanueva | U16: Inzá | V16: Pailitas | W16: Istmina | X16: Moñitos | Y16: Carmen de Carupa | AB16: Isnos | AC16: Villanueva | AD16: Pedraza | AE16: Mesetas | AF16: Cuaspud | AG16: El Zulia | AL16: Cerrito | AM16: Morroa | AN16: Falan | AO16: El Águila
B17: 16 | C17: Guainía | F17: 16 | G17: Alejandría | H17: 3 | M17: Armenia | O17: Sabanagrande | P17: Hatillo de Loba | Q17: Chinavita | R17: Norcasia | S17: Valparaíso | U17: Jambaló | V17: Pelaya | W17: Juradó | X17: Planeta Rica | Y17: Chaguaní | AB17: La Argentina | AD17: Santa Bárbara de Pinto | AE17: La Macarena | AF17: Cumbal | AG17: Gramalote | AL17: Charalá | AM17: Ovejas | AN17: Flandes | AO17: El Cairo
B18: 17 | C18: Guaviare | F18: 17 | G18: Amagá | H18: 3 | M18: Barbosa | O18: Sabanalarga | P18: Magangué | Q18: Chiquinquirá | R18: Pácora | U18: La Sierra | V18: Pueblo Bello | W18: Lloró | X18: Pueblo Nuevo | Y18: Chía | AB18: La Plata | AD18: Pivijay | AE18: Uribe | AF18: Cumbitara | AG18: Hacarí | AL18: Charta | AM18: San Antonio de Palmito | AN18: Fresno | AO18: El Cerrito
B19: 18 | C19: Huila | F19: 18 | G19: Amalfi | H19: 3 | M19: Bello | O19: Santa Lucía | P19: Mahates | Q19: Chiscas | R19: Palestina | U19: La Vega | V19: Río de Oro | W19: Medio Atrato | X19: Puerto Escondido | Y19: Chipaque | AB19: Nátaga | AD19: Plato | AE19: Lejanías | AF19: El Charco | AG19: Herrán | AL19: Chimá | AM19: Sampués | AN19: Guamo | AO19: El Dovio
B20: 19 | C20: La Guajira | F20: 19 | G20: Andes | H20: 3 | M20: Belmira | O20: Santo Tomás | P20: Margarita | Q20: Chita | R20: Pensilvania | U20: López de Micay | V20: San Alberto | W20: Medio Baudó | X20: Puerto Libertador | Y20: Choachí | AB20: Oporapa | AD20: Puebloviejo | AE20: Puerto Concordia | AF20: El Peñol | AG20: La Esperanza | AL20: Chipatá | AM20: San Benito Abad | AN20: Herveo | AO20: Florida
B21: 20 | C21: Magdalena | F21: 20 | G21: Angelópolis | H21: 3 | M21: Betania | O21: Soledad | P21: María La Baja | Q21: Chitaraque | R21: Riosucio | U21: Mercaderes | V21: San Diego | W21: Medio San Juan | X21: Purísima | Y21: Chocontá | AB21: Paicol | AD21: Remolino | AE21: Puerto Gaitán | AF21: El Rosario | AG21: La Playa de Belén | AL21: Cimitarra | AM21: San Juan de Betulia | AN21: Honda | AO21: Ginebra
B22: 21 | C22: Meta | F22: 21 | G22: Angostura | H22: 3 | M22: Betulia | O22: Suan | P22: Santa Cruz de Mompox | Q22: Chivatá | R22: Risaralda | U22: Miranda | V22: San Martín | W22: Nóvita | X22: Sahagún | Y22: Cogua | AB22: Palermo | AD22: Sabanas de San Ángel | AE22: Puerto Lleras | AF22: El Tablón | AG22: Labateca | AL22: Concepción | AM22: San Marcos | AN22: Icononzo | AO22: Guacarí
B23: 22 | C23: Nariño | F23: 22 | G23: Anorí | H23: 3 | M23: Ciudad Bolívar | O23: Tubará | P23: Montecristo | Q23: Chivor | R23: Salamina | U23: Morales | V23: Tamalameque | W23: Nuquí | X23: San Andrés de Sotavento | Y23: Cota | AB23: Palestina | AD23: Salamina | AE23: Puerto López | AF23: El Tambo | AG23: Los Patios | AL23: Confines | AM23: San Onofre | AN23: Lérida | AO23: Jamundí
B24: 23 | C24: Norte de Santander | F24: 23 | G24: Santa Fe de Antioquia | H24: 3 | M24: Briceño | O24: Usiacurí | P24: Morales | Q24: Ciénega | R24: Samaná | U24: Padilla | V24: Teorama | W24: Riosucio | X24: San Antero | Y24: Cucunubá | AB24: El Pital | AD24: San Sebastián de Buenavista | AE24: Puerto Rico | AF24: Funes | AG24: Lourdes | AL24: Contratación | AM24: San Pedro | AN24: Líbano | AO24: La Cumbre
B25: 24 | C25: Putumayo | F25: 24 | G25: Anzá | H25: 3 | M25: Buriticá | P25: Norosí | Q25: Cómbita | R25: San José | U25: Páez | V25: Urumita | W25: San José del Palmar | X25: San Bernardo del Viento | Y25: El Colegio | AB25: Pitalito | AD25: San Zenón | AE25: Restrepo | AF25: Guachucal | AG25: Mutiscua | AL25: Coromoro | AM25: Sincé | AN25: Melgar | AO25: La Unión
B26: 25 | C26: Quindío | F26: 25 | G26: Apartadó | H26: 3 | M26: Cáceres | P26: Pinillos | Q26: Coper | R26: Supía | U26: Patía | W26: Sipí | X26: San Carlos | Y26: El Peñón | AB26: Rivera | AD26: Santa Ana | AE26: San Carlos de Guaroa | AF26: Guaitarilla | AG26: Ocaña | AL26: Curití | AM26: Sucre | AN26: Murillo | AO26: La Victoria
B27: 26 | C27: Risaralda | F27: 26 | G27: Arboletes | H27: 3 | M27: Caicedo | P27: Regidor | Q27: Corrales | R27: Villamaría | U27: Piamonte | W27: Tadó | X27: San Pelayo | Y27: El Rosal | AB27: Saladoblanco | AD27: Sitionuevo | AE27: San Juan de Arama | AF27: Gualmatán | AG27: Pamplona | AL27: El Carmen de Chucurí | AM27: Tolú | AN27: Natagaima | AO27: Leiva
B28: 27 | C28: Archipiélago de San Andrés, Providencia y Santa Catalina | F28: 27 | G28: Argelia | H28: 3 | M28: Caldas | P28: Río Viejo | Q28: Covarachía | R28: Viterbo | U28: Piendamó | W28: Unguía | X28: Tierralta | Y28: Facatativá | AB28: San Agustín | AD28: Tenerife | AE28: San Juanito | AF28: Iles | AG28: Pamplonita | AL28: El Guacamayo | AM28: Toluviejo | AN28: Ortega | AO28: Obando
B29: 28 | C29: Santander | F29: 28 | G29: Armenia | H29: 3 | M29: Campamento | P29: San Cristóbal | Q29: Cubará | U29: Puerto Tejada | W29: Unión Panamericana | X29: Tuchín | Y29: Fómeque | AB29: Santa María | AD29: Zapayán | AE29: San Martín | AF29: Imués | AG29: Puerto Santander | AL29: El Peñón | AN29: Palocabildo | AO29: Palmira
B30: 29 | C30: Sucre | F30: 29 | G30: Barbosa | H30: 3 | M30: Cañasgordas | P30: San Estanislao | Q30: Cucaita | U30: Puracé-Coconuco | X30: Valencia | Y30: Fosca | AB30: Suaza | AD30: Zona Bananera | AE30: Vista Hermosa | AF30: Ipiales | AG30: Ragonvalia | AL30: El Playón | AN30: Piedras | AO30: Pradera
B31: 30 | C31: Tolima | F31: 30 | G31: Bello | H31: 3 | M31: Caracolí | P31: San Fernando | Q31: Cuítiva | U31: Rosas | Y31: Funza | AB31: Tarqui | AF31: La Cruz | AG31: Salazar de Las Palmas | AL31: Encino | AN31: Planadas | AO31: Restrepo
B32: 31 | C32: Valle del Cauca | F32: 31 | G32: Belmira | H32: 3 | M32: Caramanta | P32: San Jacinto del Cauca | Q32: Duitama | U32: San Sebastián | Y32: Fúquene | AB32: Tello | AF32: La Florida | AG32: San Calixto | AL32: Enciso | AN32: Prado | AO32: Riofrío
B33: 32 | C33: Vaupés | F33: 32 | G33: Betania | H33: 3 | M33: Carepa | P33: San Jacinto del Cauca | Q33: El Cocuy | U33: Santa Rosa | Y33: Fusagasugá | AB33: Teruel | AF33: La Llanada | AG33: San Cayetano | AL33: Florián | AN33: Purificación | AO33: Roldanillo
B34: 33 | C34: Vichada | F34: 33 | G34: Betulia | H34: 3 | M34: Carolina del Príncipe | P34: San Juan Nepomuceno | Q34: El Espino | U34: Santander de Quilichao | Y34: Gachalá | AB34: Tesalia | AF34: La Tola | AG34: Santiago | AL34: Florida Blanca | AN34: Rioblanco | AO34: San Pedro
F35: 34 | G35: Ciudad Bolívar | H35: 3 | M35: Caucasia | P35: San Martín de Loba | Q35: Firavitoba | U35: Silvia | Y35: Gachancipá | AB35: Timaná | AF35: La Unión | AG35: Sardinata | AL35: Galán | AN35: Roncesvalles | AO35: Sevilla
F36: 35 | G36: Briceño | H36: 3 | M36: Chigorodó | P36: San Pablo | Q36: Floresta | U36: Sotará | Y36: Gachetá | AB36: Villavieja | AF36: Leiva | AG36: Santo Domingo de Silos | AL36: Gámbita | AN36: Rovira | AO36: Toro
F37: 36 | G37: Buriticá | H37: 3 | M37: Cisneros | P37: Santa Catalina | Q37: Gachantivá | U37: Suárez | Y37: Gama | AB37: Yaguará | AF37: Linares | AG37: Teorama | AL37: San Juan de Girón | AN37: Saldaña | AO37: Tuluá
F38: 37 | G38: Cáceres | H38: 3 | M38: Cocorná | P38: Santa Rosa del Sur | Q38: Gámeza | U38: Sucre | Y38: Girardot | AF38: Los Andes | AG38: Toledo | AL38: Guaca | AN38: San Antonio | AO38: Tuluá
F39: 38 | G39: Caicedo | H39: 3 | M39: Concepción | P39: Santa Rosa del Sur | Q39: Garagoa | U39: Timbío | Y39: Granada | AF39: Magüí Payán | AG39: Villa Caro | AL39: Guadalupe | AN39: San Luis | AO39: Ulloa
F40: 39 | G40: Caldas | H40: 3 | M40: Concordia | P40: Simití | Q40: Guacamayas | U40: Timbiquí | Y40: Guachetá | AF40: Mallama | AG40: Villa del Rosario | AL40: Guapotá | AN40: Santa Isabel | AO40: Versalles
...

Sheet Auxiliar
A1: {=_xlfn.LET( _xlpm.matriz,_xlfn.ANCHORARRAY( Auxiliar!$C$1), _xlpm.columna_n, MATCH(TablaDatos[ [#This Row],[Tipo de empresa] ], INDEX(_xlpm.matriz, 1, 0), 0), _xlpm.rango_col, INDEX(_xlpm.matriz, 0, _xlpm.columna_n), INDEX(_xlpm.rango_col, 2) : INDEX(_xlpm.rango_col, COUNTA(_xlpm.rango_col)) )} -> #VALUE! | B1: {=_xlfn.LET( _xlpm.matriz,_xlfn.ANCHORARRAY( Auxiliar!$C$1), _xlpm.col_n, MATCH("Contratista eléctrico", INDEX(_xlpm.matriz, 1, 0), 0), _xlpm.rango_col, INDEX(_xlpm.matriz, 0, _xlpm.col_n), INDEX(_xlpm.rango_col, 2) : INDEX(_xlpm.rango_col, COUNTA(_xlpm.rango_col)) )} -> Prueba Eléctrico | C1: {=_xlfn.LET( _xlpm.tipos, TablaTipoEmpresa[Tipo empresa], IFERROR(_xlfn.DROP(_xlfn.REDUCE("", _xlpm.tipos, _xlfn.LAMBDA(_xlpm.matriz,_xlpm.t, _xlfn.HSTACK(_xlpm.matriz, _xlfn.VSTACK(_xlpm.t, _xlfn._xlws.FILTER(TablaEmpresas[Empresa], TablaEmpresas[Tipo de empresa]=_xlpm.t, "" ))))), , 1), "") )} -> Constructora | D1: Contratista eléctrico | E1: Industria | F1: Distribuidora | H1: {=_xlfn.LET( _xlpm.matriz,_xlfn.ANCHORARRAY( Auxiliar!$C$1), _xlpm.col_n, MATCH("Contratista eléctrico", INDEX(_xlpm.matriz, 1, 0), 0), _xlpm.rango_col, INDEX(_xlpm.matriz, 0, _xlpm.col_n), INDEX(_xlpm.rango_col, 2) : INDEX(_xlpm.rango_col, COUNTA(_xlpm.rango_col)) )} -> Prueba Eléctrico | Z1: {=_xlfn.LET( _xlpm.m,_xlfn.ANCHORARRAY( Auxiliar!$AA$1), _xlpm.sel, INDIRECT("FC[-1]", 0), _xlpm.f, IFERROR(MATCH(_xlpm.sel, INDEX(_xlpm.m,,1), 0), 0), IF(_xlpm.f=0, Auxiliar!$Z$10, _xlfn.LET( _xlpm.fila, INDEX(_xlpm.m, _xlpm.f, 0), _xlpm.inicio, INDEX(_xlpm.fila, 2), _xlpm.fin, INDEX(_xlpm.fila, COUNTA(_xlpm.fila)), _xlpm.inicio:_xlpm.fin ) ) )} -> 0 | AA1: {=_xlfn.LET( _xlpm.lista_cruda, _xlfn.UNIQUE(TablaContactos[Empresa]), _xlpm.empresas, _xlfn._xlws.FILTER(_xlpm.lista_cruda, (_xlpm.lista_cruda<>"")*(_xlpm.lista_cruda<>0), "Sin empresas"), IFERROR(_xlfn.DROP(_xlfn.REDUCE("", _xlpm.empresas, _xlfn.LAMBDA(_xlpm.matriz,_xlpm.e, _xlfn.VSTACK(_xlpm.matriz, _xlfn.HSTACK(_xlpm.e, TRANSPOSE(_xlfn._xlws.FILTER(TablaContactos[Contacto], TablaContactos[Empresa]=_xlpm.e, "" )))) )), 1, ), "") )} -> INDELPA SAS | AB1: Ing. Jhonier Puerta Ospina | AC1: Ing. Julian Nieto Cruz
A2: {=_xlfn.LET( _xlpm.matriz,_xlfn.ANCHORARRAY( Auxiliar!$C$1), _xlpm.tipo, INDIRECT("FC[-1]", FALSE), _xlpm.col_n, IFERROR(MATCH(_xlpm.tipo, INDEX(_xlpm.matriz, 1, 0), 0), 0), IF(_xlpm.col_n=0, Auxiliar!$XAA$1, _xlfn.LET( _xlpm.rango_col, INDEX(_xlpm.matriz, 0, _xlpm.col_n), INDEX(_xlpm.rango_col, 2) : INDEX(_xlpm.rango_col, COUNTA(_xlpm.rango_col)) ) ) )} -> 0 | C2: Prueba Constructora | D2: Prueba Eléctrico | E2: INDELPA SAS | F2: Prueba Distribuidor | AA2: Prueba Constructora | AB2: Contacto constructora
AA3: Prueba Eléctrico | AB3: Contacto eléctrico

Sheet Empresa
B1: Empresa | C1: Tipo de empresa | D1: Telefono | E1: Celular | F1: Correo | G1: Departamento | H1: Ciudad | I1: Dirección | J1: Notas
B2: INDELPA SAS | C2: Industria | E2: 310 627 9267 | F2: ventas@indelpa.com | G2: Risaralda | H2: Dosquebradas | I2: Carrera 16 #8-138, barrio Valher
B3: Prueba Constructora | C3: Constructora | E3: 111 111 11 11 | F3: prueba@constructora.com | G3: Antioquia | H3: Medellín | I3: Cra 16a # 78-55
B4: Prueba Distribuidor | C4: Distribuidora | D4: 608 2771548 | E4: 222 222 22 22 | F4: prueba@distribuidora.com | G4: Tolima | H4: Ibagué | I4: Calle 24 # 4A-26
B5: Prueba Eléctrico | C5: Contratista eléctrico | D5: 601 7310383 | E5: 333 333 33 33 | F5: prueba@constructoraelectrico.com | G5: Bogotá | H5: Bogotá | I5: Cl. 71 #19-50

Sheet Contactos
B1: Contacto | C1: Tipo de empresa | D1: Empresa | E1: Cargo | F1: Celular | G1: Correo | H1: Notas
B2: Ing. Jhonier Puerta Ospina | C2: Industria | D2: INDELPA SAS | E2: Comercial | F2: 320 267 6670 | G2: jpuerta@indelpa.com
B3: Ing. Julian Nieto Cruz | C3: Industria | D3: INDELPA SAS | E3: Comercial | F3: +57 310 6149989 | G3: d.electrico@indelpa.com
B4: Contacto constructora | C4: Constructora | D4: Prueba Constructora | E4: Director de obra | F4: 111 111 11 11 | G4: director@prueba.com
B5: Contacto eléctrico | C5: Contratista eléctrico | D5: Prueba Eléctrico | E5: Coordinado de compras | F5: 222 222 22 22 | G5: compras@prueba.com | H5: Cita agendada para el 27/3/26

Sheet Listas
B2: Estado | C2: No cotizado | D2: Cotizado | E2: Descripción Fase | F2: ¿Quién compra? | G2: ¿Cotizado? | I2: Vendedor | J2: Nombre | L2: Tipo empresa
B3: Ventas sobre planos | C3: Blanco | D3: Naranja | F3: Empresa | G3: Si | I3: JPO | J3: Jhonier Puerta | L3: Constructora | R3: {=_xlfn._xlws.FILTER(TablaEmpresas[Empresa],R2=TablaEmpresas[Tipo de empresa],"")}
B4: Preparación del Terreno y cimentación | C4: Blanco | D4: Naranja | F4: Contratista | G4: No | I4: JNC | J4: Julian Nieto | L4: Contratista eléctrico
B5: Estructura | C5: Rosa | D5: ROJO | E5: (Columnas, vigas, losas) | I5: BER | J5: Binsen Rios | L5: Industria
B6: Cerramientos y Fachada | C6: Rosa | D6: ROJO | E6: (Muros, ventanas, acabado exterior) | I6: EAL | J6: Esteban Agudelo | L6: Distribuidora
B7: Ya compraron subestación | C7: Gris | D7: GIRS | E7: Proyecto asignado a Indelpa o terceros | I7: MRA | J7: Mariana Ruiz
I8: OVS | J8: Orly Vides
B12: 1. Planeación y Diseño (3-6 meses) - Estudios, diseños, permisos
B13: 2. Preparación del Terreno (1-2 meses) - Limpieza, cerramientos, accesos | E13: Código de colores | F13: Estado
B14: 3. Cimentación (2-4 meses) - Excavación, zapatas, placas | E14: Blanco | F14: No cotizado, en planos o preparación de Terreno
B15: 4. Estructura (4-8 meses) - Columnas, vigas, losas | E15: Naranja | F15: Cotizado, en planos o preparación de Terreno
B16: 5. Cerramientos y Fachada (2-4 meses) - Muros, ventanas, acabado exterior | E16: Rosa | F16: No cotizado, en estructura o cerramientos
B17: 6. Instalaciones Técnicas (3-6 meses) - FASE CRÍTICA PARA TABLEROS ELÉCTRICOS ⚡ | E17: Rojo | F17: Cotizado, en estructura o cerramientos
B18: 7. Acabados Interiores (3-5 meses) - Pisos, pinturas, carpintería | E18: Gris | F18: Proyecto asignado a Indelpa o terceros
B19: 8. Áreas Comunes y Urbanización (1-2 meses) - Zonas verdes, estacionamientos | E19: Marrón | F19: Sin seguimiento hace más de 2 meses
B20: 9. Equipamiento y Pruebas Finales (1-2 meses) - Ascensores, certificaciones
B21: 10. Entrega y Postventa (Continuo) - Garantía y mantenimiento
